[2024-07-30T22:38:22.723+0000] {local_task_job_runner.py:120} INFO - ::group::Pre task execution logs
[2024-07-30T22:38:22.740+0000] {taskinstance.py:2076} INFO - Dependencies all met for dep_context=non-requeueable deps ti=<TaskInstance: etl_dag.extract manual__2024-07-30T22:38:19.716846+00:00 [queued]>
[2024-07-30T22:38:22.744+0000] {taskinstance.py:2076} INFO - Dependencies all met for dep_context=requeueable deps ti=<TaskInstance: etl_dag.extract manual__2024-07-30T22:38:19.716846+00:00 [queued]>
[2024-07-30T22:38:22.744+0000] {taskinstance.py:2306} INFO - Starting attempt 1 of 2
[2024-07-30T22:38:22.751+0000] {taskinstance.py:2330} INFO - Executing <Task(PythonOperator): extract> on 2024-07-30 22:38:19.716846+00:00
[2024-07-30T22:38:22.767+0000] {warnings.py:112} WARNING - /home/***/.local/lib/python3.12/site-packages/***/task/task_runner/standard_task_runner.py:62: DeprecationWarning: This process (pid=262) is multi-threaded, use of fork() may lead to deadlocks in the child.
  pid = os.fork()

[2024-07-30T22:38:22.773+0000] {standard_task_runner.py:64} INFO - Started process 264 to run task
[2024-07-30T22:38:22.767+0000] {standard_task_runner.py:90} INFO - Running: ['***', 'tasks', 'run', 'etl_dag', 'extract', 'manual__2024-07-30T22:38:19.716846+00:00', '--job-id', '11', '--raw', '--subdir', 'DAGS_FOLDER/etl_dag.py', '--cfg-path', '/tmp/tmp5rng5s0l']
[2024-07-30T22:38:22.780+0000] {standard_task_runner.py:91} INFO - Job 11: Subtask extract
[2024-07-30T22:38:22.868+0000] {task_command.py:426} INFO - Running <TaskInstance: etl_dag.extract manual__2024-07-30T22:38:19.716846+00:00 [running]> on host bb49ef30ae89
[2024-07-30T22:38:22.940+0000] {taskinstance.py:2648} INFO - Exporting env vars: AIRFLOW_CTX_DAG_OWNER='***' AIRFLOW_CTX_DAG_ID='etl_dag' AIRFLOW_CTX_TASK_ID='extract' AIRFLOW_CTX_EXECUTION_DATE='2024-07-30T22:38:19.716846+00:00' AIRFLOW_CTX_TRY_NUMBER='1' AIRFLOW_CTX_DAG_RUN_ID='manual__2024-07-30T22:38:19.716846+00:00'
[2024-07-30T22:38:22.949+0000] {taskinstance.py:430} INFO - ::endgroup::
[2024-07-30T22:38:22.958+0000] {taskinstance.py:441} INFO - ::group::Post task execution logs
[2024-07-30T22:38:22.964+0000] {taskinstance.py:2905} ERROR - Task failed with exception
Traceback (most recent call last):
  File "/home/airflow/.local/lib/python3.12/site-packages/airflow/models/taskinstance.py", line 465, in _execute_task
    result = _execute_callable(context=context, **execute_callable_kwargs)
             ^^^^^^^^^^^^^^^^^^^^^^^^^^^^^^^^^^^^^^^^^^^^^^^^^^^^^^^^^^^^^
  File "/home/airflow/.local/lib/python3.12/site-packages/airflow/models/taskinstance.py", line 432, in _execute_callable
    return execute_callable(context=context, **execute_callable_kwargs)
           ^^^^^^^^^^^^^^^^^^^^^^^^^^^^^^^^^^^^^^^^^^^^^^^^^^^^^^^^^^^^
  File "/home/airflow/.local/lib/python3.12/site-packages/airflow/models/baseoperator.py", line 401, in wrapper
    return func(self, *args, **kwargs)
           ^^^^^^^^^^^^^^^^^^^^^^^^^^^
  File "/home/airflow/.local/lib/python3.12/site-packages/airflow/operators/python.py", line 235, in execute
    return_value = self.execute_callable()
                   ^^^^^^^^^^^^^^^^^^^^^^^
  File "/home/airflow/.local/lib/python3.12/site-packages/airflow/operators/python.py", line 252, in execute_callable
    return self.python_callable(*self.op_args, **self.op_kwargs)
           ^^^^^^^^^^^^^^^^^^^^^^^^^^^^^^^^^^^^^^^^^^^^^^^^^^^^^
  File "/opt/airflow/dags/etl/extract.py", line 8, in extract_data
    connection = BaseHook.get_connection(conn_id)
                 ^^^^^^^^^^^^^^^^^^^^^^^^^^^^^^^^
  File "/home/airflow/.local/lib/python3.12/site-packages/airflow/hooks/base.py", line 83, in get_connection
    conn = Connection.get_connection_from_secrets(conn_id)
           ^^^^^^^^^^^^^^^^^^^^^^^^^^^^^^^^^^^^^^^^^^^^^^^
  File "/home/airflow/.local/lib/python3.12/site-packages/airflow/models/connection.py", line 519, in get_connection_from_secrets
    raise AirflowNotFoundException(f"The conn_id `{conn_id}` isn't defined")
airflow.exceptions.AirflowNotFoundException: The conn_id `my_api_connection` isn't defined
[2024-07-30T22:38:22.973+0000] {taskinstance.py:1206} INFO - Marking task as UP_FOR_RETRY. dag_id=etl_dag, task_id=extract, run_id=manual__2024-07-30T22:38:19.716846+00:00, execution_date=20240730T223819, start_date=20240730T223822, end_date=20240730T223822
[2024-07-30T22:38:22.981+0000] {standard_task_runner.py:110} ERROR - Failed to execute job 11 for task extract (The conn_id `my_api_connection` isn't defined; 264)
[2024-07-30T22:38:23.006+0000] {local_task_job_runner.py:243} INFO - Task exited with return code 1
[2024-07-30T22:38:23.027+0000] {taskinstance.py:3503} INFO - 0 downstream tasks scheduled from follow-on schedule check
[2024-07-30T22:38:23.029+0000] {local_task_job_runner.py:222} INFO - ::endgroup::
