[2024-08-05T01:09:05.876+0000] {local_task_job_runner.py:120} INFO - ::group::Pre task execution logs
[2024-08-05T01:09:05.887+0000] {taskinstance.py:2076} INFO - Dependencies all met for dep_context=non-requeueable deps ti=<TaskInstance: etl_dag.carga_fatoemailmarketing manual__2024-08-05T01:08:50.566450+00:00 [queued]>
[2024-08-05T01:09:05.891+0000] {taskinstance.py:2076} INFO - Dependencies all met for dep_context=requeueable deps ti=<TaskInstance: etl_dag.carga_fatoemailmarketing manual__2024-08-05T01:08:50.566450+00:00 [queued]>
[2024-08-05T01:09:05.891+0000] {taskinstance.py:2306} INFO - Starting attempt 1 of 6
[2024-08-05T01:09:05.896+0000] {taskinstance.py:2330} INFO - Executing <Task(PythonOperator): carga_fatoemailmarketing> on 2024-08-05 01:08:50.566450+00:00
[2024-08-05T01:09:05.903+0000] {warnings.py:112} WARNING - /home/***/.local/lib/python3.12/site-packages/***/task/task_runner/standard_task_runner.py:62: DeprecationWarning: This process (pid=710) is multi-threaded, use of fork() may lead to deadlocks in the child.
  pid = os.fork()

[2024-08-05T01:09:05.904+0000] {standard_task_runner.py:64} INFO - Started process 712 to run task
[2024-08-05T01:09:05.904+0000] {standard_task_runner.py:90} INFO - Running: ['***', 'tasks', 'run', 'etl_dag', 'carga_fatoemailmarketing', 'manual__2024-08-05T01:08:50.566450+00:00', '--job-id', '1695', '--raw', '--subdir', 'DAGS_FOLDER/etl_dag.py', '--cfg-path', '/tmp/tmpa8zjcm1g']
[2024-08-05T01:09:05.906+0000] {standard_task_runner.py:91} INFO - Job 1695: Subtask carga_fatoemailmarketing
[2024-08-05T01:09:05.947+0000] {task_command.py:426} INFO - Running <TaskInstance: etl_dag.carga_fatoemailmarketing manual__2024-08-05T01:08:50.566450+00:00 [running]> on host 59ce2ba01338
[2024-08-05T01:09:05.994+0000] {taskinstance.py:2648} INFO - Exporting env vars: AIRFLOW_CTX_DAG_OWNER='Gabriel Almeida' AIRFLOW_CTX_DAG_ID='etl_dag' AIRFLOW_CTX_TASK_ID='carga_fatoemailmarketing' AIRFLOW_CTX_EXECUTION_DATE='2024-08-05T01:08:50.566450+00:00' AIRFLOW_CTX_TRY_NUMBER='1' AIRFLOW_CTX_DAG_RUN_ID='manual__2024-08-05T01:08:50.566450+00:00'
[2024-08-05T01:09:05.994+0000] {taskinstance.py:430} INFO - ::endgroup::
[2024-08-05T01:09:06.080+0000] {base.py:84} INFO - Using connection ID 'postgres_conn' for task execution.
[2024-08-05T01:09:06.097+0000] {taskinstance.py:441} INFO - ::group::Post task execution logs
[2024-08-05T01:09:06.098+0000] {taskinstance.py:2905} ERROR - Task failed with exception
Traceback (most recent call last):
  File "/home/airflow/.local/lib/python3.12/site-packages/airflow/models/taskinstance.py", line 465, in _execute_task
    result = _execute_callable(context=context, **execute_callable_kwargs)
             ^^^^^^^^^^^^^^^^^^^^^^^^^^^^^^^^^^^^^^^^^^^^^^^^^^^^^^^^^^^^^
  File "/home/airflow/.local/lib/python3.12/site-packages/airflow/models/taskinstance.py", line 432, in _execute_callable
    return execute_callable(context=context, **execute_callable_kwargs)
           ^^^^^^^^^^^^^^^^^^^^^^^^^^^^^^^^^^^^^^^^^^^^^^^^^^^^^^^^^^^^
  File "/home/airflow/.local/lib/python3.12/site-packages/airflow/models/baseoperator.py", line 401, in wrapper
    return func(self, *args, **kwargs)
           ^^^^^^^^^^^^^^^^^^^^^^^^^^^
  File "/home/airflow/.local/lib/python3.12/site-packages/airflow/operators/python.py", line 235, in execute
    return_value = self.execute_callable()
                   ^^^^^^^^^^^^^^^^^^^^^^^
  File "/home/airflow/.local/lib/python3.12/site-packages/airflow/operators/python.py", line 252, in execute_callable
    return self.python_callable(*self.op_args, **self.op_kwargs)
           ^^^^^^^^^^^^^^^^^^^^^^^^^^^^^^^^^^^^^^^^^^^^^^^^^^^^^
  File "/opt/airflow/dags/etl/dim_load.py", line 77, in load_fatoemailmarketing
    cursor.execute(f"""
psycopg2.errors.UniqueViolation: duplicate key value violates unique constraint "fatoemailmarketing_pkey"
DETAIL:  Key (id)=(1811728) already exists.

[2024-08-05T01:09:06.106+0000] {taskinstance.py:1206} INFO - Marking task as UP_FOR_RETRY. dag_id=etl_dag, task_id=carga_fatoemailmarketing, run_id=manual__2024-08-05T01:08:50.566450+00:00, execution_date=20240805T010850, start_date=20240805T010905, end_date=20240805T010906
[2024-08-05T01:09:06.120+0000] {standard_task_runner.py:110} ERROR - Failed to execute job 1695 for task carga_fatoemailmarketing (duplicate key value violates unique constraint "fatoemailmarketing_pkey"
DETAIL:  Key (id)=(1811728) already exists.
; 712)
[2024-08-05T01:09:06.167+0000] {local_task_job_runner.py:243} INFO - Task exited with return code 1
[2024-08-05T01:09:06.182+0000] {taskinstance.py:3503} INFO - 0 downstream tasks scheduled from follow-on schedule check
[2024-08-05T01:09:06.183+0000] {local_task_job_runner.py:222} INFO - ::endgroup::
