[2024-08-02T14:05:49.938+0000] {local_task_job_runner.py:120} INFO - ::group::Pre task execution logs
[2024-08-02T14:05:50.006+0000] {taskinstance.py:2076} INFO - Dependencies all met for dep_context=non-requeueable deps ti=<TaskInstance: etl_dag.Carga_Dimensao_user_type scheduled__2024-08-02T11:50:00+00:00 [queued]>
[2024-08-02T14:05:50.038+0000] {taskinstance.py:2076} INFO - Dependencies all met for dep_context=requeueable deps ti=<TaskInstance: etl_dag.Carga_Dimensao_user_type scheduled__2024-08-02T11:50:00+00:00 [queued]>
[2024-08-02T14:05:50.039+0000] {taskinstance.py:2306} INFO - Starting attempt 6 of 6
[2024-08-02T14:05:50.082+0000] {taskinstance.py:2330} INFO - Executing <Task(PythonOperator): Carga_Dimensao_user_type> on 2024-08-02 11:50:00+00:00
[2024-08-02T14:05:50.111+0000] {standard_task_runner.py:90} INFO - Running: ['***', 'tasks', 'run', 'etl_dag', 'Carga_Dimensao_user_type', 'scheduled__2024-08-02T11:50:00+00:00', '--job-id', '412', '--raw', '--subdir', 'DAGS_FOLDER/etl_dag.py', '--cfg-path', '/tmp/tmpb2mmmdk7']
[2024-08-02T14:05:50.110+0000] {warnings.py:112} WARNING - /home/***/.local/lib/python3.12/site-packages/***/task/task_runner/standard_task_runner.py:62: DeprecationWarning: This process (pid=2128) is multi-threaded, use of fork() may lead to deadlocks in the child.
  pid = os.fork()

[2024-08-02T14:05:50.115+0000] {standard_task_runner.py:91} INFO - Job 412: Subtask Carga_Dimensao_user_type
[2024-08-02T14:05:50.115+0000] {standard_task_runner.py:64} INFO - Started process 2199 to run task
[2024-08-02T14:05:50.263+0000] {task_command.py:426} INFO - Running <TaskInstance: etl_dag.Carga_Dimensao_user_type scheduled__2024-08-02T11:50:00+00:00 [running]> on host 69633e19c226
[2024-08-02T14:05:50.506+0000] {taskinstance.py:2648} INFO - Exporting env vars: AIRFLOW_CTX_DAG_OWNER='Gabriel Almeida' AIRFLOW_CTX_DAG_ID='etl_dag' AIRFLOW_CTX_TASK_ID='Carga_Dimensao_user_type' AIRFLOW_CTX_EXECUTION_DATE='2024-08-02T11:50:00+00:00' AIRFLOW_CTX_TRY_NUMBER='6' AIRFLOW_CTX_DAG_RUN_ID='scheduled__2024-08-02T11:50:00+00:00'
[2024-08-02T14:05:50.511+0000] {taskinstance.py:430} INFO - ::endgroup::
[2024-08-02T14:05:50.747+0000] {base.py:84} INFO - Using connection ID 'postgres_conn' for task execution.
[2024-08-02T14:05:50.879+0000] {logging_mixin.py:188} INFO -   user_type
0      Lead
[2024-08-02T14:05:50.899+0000] {taskinstance.py:441} INFO - ::group::Post task execution logs
[2024-08-02T14:05:50.924+0000] {taskinstance.py:2905} ERROR - Task failed with exception
Traceback (most recent call last):
  File "/home/airflow/.local/lib/python3.12/site-packages/airflow/models/taskinstance.py", line 465, in _execute_task
    result = _execute_callable(context=context, **execute_callable_kwargs)
             ^^^^^^^^^^^^^^^^^^^^^^^^^^^^^^^^^^^^^^^^^^^^^^^^^^^^^^^^^^^^^
  File "/home/airflow/.local/lib/python3.12/site-packages/airflow/models/taskinstance.py", line 432, in _execute_callable
    return execute_callable(context=context, **execute_callable_kwargs)
           ^^^^^^^^^^^^^^^^^^^^^^^^^^^^^^^^^^^^^^^^^^^^^^^^^^^^^^^^^^^^
  File "/home/airflow/.local/lib/python3.12/site-packages/airflow/models/baseoperator.py", line 401, in wrapper
    return func(self, *args, **kwargs)
           ^^^^^^^^^^^^^^^^^^^^^^^^^^^
  File "/home/airflow/.local/lib/python3.12/site-packages/airflow/operators/python.py", line 235, in execute
    return_value = self.execute_callable()
                   ^^^^^^^^^^^^^^^^^^^^^^^
  File "/home/airflow/.local/lib/python3.12/site-packages/airflow/operators/python.py", line 252, in execute_callable
    return self.python_callable(*self.op_args, **self.op_kwargs)
           ^^^^^^^^^^^^^^^^^^^^^^^^^^^^^^^^^^^^^^^^^^^^^^^^^^^^^
  File "/opt/airflow/dags/etl/dim_load.py", line 19, in load_dim_user_type
    cursor.execute(f"""
psycopg2.errors.UndefinedColumn: column "lead" does not exist
LINE 3:             VALUES (Lead)
                            ^

[2024-08-02T14:05:51.012+0000] {taskinstance.py:1206} INFO - Marking task as FAILED. dag_id=etl_dag, task_id=Carga_Dimensao_user_type, run_id=scheduled__2024-08-02T11:50:00+00:00, execution_date=20240802T115000, start_date=20240802T140550, end_date=20240802T140551
[2024-08-02T14:05:51.057+0000] {standard_task_runner.py:110} ERROR - Failed to execute job 412 for task Carga_Dimensao_user_type (column "lead" does not exist
LINE 3:             VALUES (Lead)
                            ^
; 2199)
[2024-08-02T14:05:51.132+0000] {local_task_job_runner.py:243} INFO - Task exited with return code 1
[2024-08-02T14:05:51.241+0000] {taskinstance.py:3503} INFO - 0 downstream tasks scheduled from follow-on schedule check
[2024-08-02T14:05:51.251+0000] {local_task_job_runner.py:222} INFO - ::endgroup::
