[2024-08-01T17:07:12.688+0000] {local_task_job_runner.py:120} INFO - ::group::Pre task execution logs
[2024-08-01T17:07:12.709+0000] {taskinstance.py:2076} INFO - Dependencies all met for dep_context=non-requeueable deps ti=<TaskInstance: etl_dag.create_dim_campaign scheduled__2024-08-01T16:55:00+00:00 [queued]>
[2024-08-01T17:07:12.714+0000] {taskinstance.py:2076} INFO - Dependencies all met for dep_context=requeueable deps ti=<TaskInstance: etl_dag.create_dim_campaign scheduled__2024-08-01T16:55:00+00:00 [queued]>
[2024-08-01T17:07:12.716+0000] {taskinstance.py:2306} INFO - Starting attempt 3 of 6
[2024-08-01T17:07:12.729+0000] {taskinstance.py:2330} INFO - Executing <Task(PostgresOperator): create_dim_campaign> on 2024-08-01 16:55:00+00:00
[2024-08-01T17:07:12.766+0000] {warnings.py:112} WARNING - /home/***/.local/lib/python3.12/site-packages/***/task/task_runner/standard_task_runner.py:62: DeprecationWarning: This process (pid=716) is multi-threaded, use of fork() may lead to deadlocks in the child.
  pid = os.fork()

[2024-08-01T17:07:12.769+0000] {standard_task_runner.py:64} INFO - Started process 722 to run task
[2024-08-01T17:07:12.771+0000] {standard_task_runner.py:90} INFO - Running: ['***', 'tasks', 'run', 'etl_dag', 'create_dim_campaign', 'scheduled__2024-08-01T16:55:00+00:00', '--job-id', '123', '--raw', '--subdir', 'DAGS_FOLDER/etl_dag.py', '--cfg-path', '/tmp/tmp0m5pncyb']
[2024-08-01T17:07:12.772+0000] {standard_task_runner.py:91} INFO - Job 123: Subtask create_dim_campaign
[2024-08-01T17:07:12.837+0000] {task_command.py:426} INFO - Running <TaskInstance: etl_dag.create_dim_campaign scheduled__2024-08-01T16:55:00+00:00 [running]> on host e27a9ccca098
[2024-08-01T17:07:12.971+0000] {taskinstance.py:2648} INFO - Exporting env vars: AIRFLOW_CTX_DAG_OWNER='Gabriel Almeida' AIRFLOW_CTX_DAG_ID='etl_dag' AIRFLOW_CTX_TASK_ID='create_dim_campaign' AIRFLOW_CTX_EXECUTION_DATE='2024-08-01T16:55:00+00:00' AIRFLOW_CTX_TRY_NUMBER='3' AIRFLOW_CTX_DAG_RUN_ID='scheduled__2024-08-01T16:55:00+00:00'
[2024-08-01T17:07:12.973+0000] {taskinstance.py:430} INFO - ::endgroup::
[2024-08-01T17:07:12.973+0000] {sql.py:282} INFO - Executing: 
            CREATE TABLE IF NOT EXISTS DimCampaign (
                id_campaign INT PRIMARY KEY,
                campaign VARCHAR(255)
            );
        
[2024-08-01T17:07:12.980+0000] {taskinstance.py:441} INFO - ::group::Post task execution logs
[2024-08-01T17:07:12.995+0000] {taskinstance.py:2905} ERROR - Task failed with exception
Traceback (most recent call last):
  File "/home/airflow/.local/lib/python3.12/site-packages/airflow/models/taskinstance.py", line 465, in _execute_task
    result = _execute_callable(context=context, **execute_callable_kwargs)
             ^^^^^^^^^^^^^^^^^^^^^^^^^^^^^^^^^^^^^^^^^^^^^^^^^^^^^^^^^^^^^
  File "/home/airflow/.local/lib/python3.12/site-packages/airflow/models/taskinstance.py", line 432, in _execute_callable
    return execute_callable(context=context, **execute_callable_kwargs)
           ^^^^^^^^^^^^^^^^^^^^^^^^^^^^^^^^^^^^^^^^^^^^^^^^^^^^^^^^^^^^
  File "/home/airflow/.local/lib/python3.12/site-packages/airflow/models/baseoperator.py", line 401, in wrapper
    return func(self, *args, **kwargs)
           ^^^^^^^^^^^^^^^^^^^^^^^^^^^
  File "/home/airflow/.local/lib/python3.12/site-packages/airflow/providers/common/sql/operators/sql.py", line 283, in execute
    hook = self.get_db_hook()
           ^^^^^^^^^^^^^^^^^^
  File "/home/airflow/.local/lib/python3.12/site-packages/airflow/providers/common/sql/operators/sql.py", line 194, in get_db_hook
    return self._hook
           ^^^^^^^^^^
  File "/usr/local/lib/python3.12/functools.py", line 995, in __get__
    val = self.func(instance)
          ^^^^^^^^^^^^^^^^^^^
  File "/home/airflow/.local/lib/python3.12/site-packages/airflow/providers/common/sql/operators/sql.py", line 153, in _hook
    conn = BaseHook.get_connection(conn_id)
           ^^^^^^^^^^^^^^^^^^^^^^^^^^^^^^^^
  File "/home/airflow/.local/lib/python3.12/site-packages/airflow/hooks/base.py", line 83, in get_connection
    conn = Connection.get_connection_from_secrets(conn_id)
           ^^^^^^^^^^^^^^^^^^^^^^^^^^^^^^^^^^^^^^^^^^^^^^^
  File "/home/airflow/.local/lib/python3.12/site-packages/airflow/models/connection.py", line 519, in get_connection_from_secrets
    raise AirflowNotFoundException(f"The conn_id `{conn_id}` isn't defined")
airflow.exceptions.AirflowNotFoundException: The conn_id `your_postgres_connection` isn't defined
[2024-08-01T17:07:13.006+0000] {taskinstance.py:1206} INFO - Marking task as UP_FOR_RETRY. dag_id=etl_dag, task_id=create_dim_campaign, run_id=scheduled__2024-08-01T16:55:00+00:00, execution_date=20240801T165500, start_date=20240801T170712, end_date=20240801T170713
[2024-08-01T17:07:13.015+0000] {standard_task_runner.py:110} ERROR - Failed to execute job 123 for task create_dim_campaign (The conn_id `your_postgres_connection` isn't defined; 722)
[2024-08-01T17:07:13.036+0000] {local_task_job_runner.py:243} INFO - Task exited with return code 1
[2024-08-01T17:07:13.055+0000] {taskinstance.py:3503} INFO - 0 downstream tasks scheduled from follow-on schedule check
[2024-08-01T17:07:13.065+0000] {local_task_job_runner.py:222} INFO - ::endgroup::
