[2024-08-02T12:19:43.063+0000] {local_task_job_runner.py:120} INFO - ::group::Pre task execution logs
[2024-08-02T12:19:43.153+0000] {taskinstance.py:2076} INFO - Dependencies all met for dep_context=non-requeueable deps ti=<TaskInstance: etl_dag.Carga_Dimensao_user_type scheduled__2024-08-02T11:10:00+00:00 [queued]>
[2024-08-02T12:19:43.203+0000] {taskinstance.py:2076} INFO - Dependencies all met for dep_context=requeueable deps ti=<TaskInstance: etl_dag.Carga_Dimensao_user_type scheduled__2024-08-02T11:10:00+00:00 [queued]>
[2024-08-02T12:19:43.210+0000] {taskinstance.py:2306} INFO - Starting attempt 6 of 6
[2024-08-02T12:19:43.298+0000] {taskinstance.py:2330} INFO - Executing <Task(PythonOperator): Carga_Dimensao_user_type> on 2024-08-02 11:10:00+00:00
[2024-08-02T12:19:43.348+0000] {warnings.py:112} WARNING - /home/***/.local/lib/python3.12/site-packages/***/task/task_runner/standard_task_runner.py:62: DeprecationWarning: This process (pid=1825) is multi-threaded, use of fork() may lead to deadlocks in the child.
  pid = os.fork()

[2024-08-02T12:19:43.362+0000] {standard_task_runner.py:64} INFO - Started process 1835 to run task
[2024-08-02T12:19:43.379+0000] {standard_task_runner.py:90} INFO - Running: ['***', 'tasks', 'run', 'etl_dag', 'Carga_Dimensao_user_type', 'scheduled__2024-08-02T11:10:00+00:00', '--job-id', '363', '--raw', '--subdir', 'DAGS_FOLDER/etl_dag.py', '--cfg-path', '/tmp/tmpvl4aq5ec']
[2024-08-02T12:19:43.382+0000] {standard_task_runner.py:91} INFO - Job 363: Subtask Carga_Dimensao_user_type
[2024-08-02T12:19:43.554+0000] {task_command.py:426} INFO - Running <TaskInstance: etl_dag.Carga_Dimensao_user_type scheduled__2024-08-02T11:10:00+00:00 [running]> on host 69633e19c226
[2024-08-02T12:19:43.813+0000] {taskinstance.py:2648} INFO - Exporting env vars: AIRFLOW_CTX_DAG_OWNER='Gabriel Almeida' AIRFLOW_CTX_DAG_ID='etl_dag' AIRFLOW_CTX_TASK_ID='Carga_Dimensao_user_type' AIRFLOW_CTX_EXECUTION_DATE='2024-08-02T11:10:00+00:00' AIRFLOW_CTX_TRY_NUMBER='6' AIRFLOW_CTX_DAG_RUN_ID='scheduled__2024-08-02T11:10:00+00:00'
[2024-08-02T12:19:43.842+0000] {taskinstance.py:430} INFO - ::endgroup::
[2024-08-02T12:19:44.292+0000] {base.py:84} INFO - Using connection ID 'postgres_conn' for task execution.
[2024-08-02T12:19:44.360+0000] {logging_mixin.py:188} INFO -   user_type
0      Lead
[2024-08-02T12:19:44.367+0000] {taskinstance.py:441} INFO - ::group::Post task execution logs
[2024-08-02T12:19:44.371+0000] {taskinstance.py:2905} ERROR - Task failed with exception
Traceback (most recent call last):
  File "/home/airflow/.local/lib/python3.12/site-packages/airflow/models/taskinstance.py", line 465, in _execute_task
    result = _execute_callable(context=context, **execute_callable_kwargs)
             ^^^^^^^^^^^^^^^^^^^^^^^^^^^^^^^^^^^^^^^^^^^^^^^^^^^^^^^^^^^^^
  File "/home/airflow/.local/lib/python3.12/site-packages/airflow/models/taskinstance.py", line 432, in _execute_callable
    return execute_callable(context=context, **execute_callable_kwargs)
           ^^^^^^^^^^^^^^^^^^^^^^^^^^^^^^^^^^^^^^^^^^^^^^^^^^^^^^^^^^^^
  File "/home/airflow/.local/lib/python3.12/site-packages/airflow/models/baseoperator.py", line 401, in wrapper
    return func(self, *args, **kwargs)
           ^^^^^^^^^^^^^^^^^^^^^^^^^^^
  File "/home/airflow/.local/lib/python3.12/site-packages/airflow/operators/python.py", line 235, in execute
    return_value = self.execute_callable()
                   ^^^^^^^^^^^^^^^^^^^^^^^
  File "/home/airflow/.local/lib/python3.12/site-packages/airflow/operators/python.py", line 252, in execute_callable
    return self.python_callable(*self.op_args, **self.op_kwargs)
           ^^^^^^^^^^^^^^^^^^^^^^^^^^^^^^^^^^^^^^^^^^^^^^^^^^^^^
  File "/opt/airflow/dags/etl/dim_load.py", line 19, in load_dim_user_type
    cursor.execute(f"""
psycopg2.errors.UndefinedColumn: column "lead" does not exist
LINE 3:             VALUES (Lead)
                            ^

[2024-08-02T12:19:44.406+0000] {taskinstance.py:1206} INFO - Marking task as FAILED. dag_id=etl_dag, task_id=Carga_Dimensao_user_type, run_id=scheduled__2024-08-02T11:10:00+00:00, execution_date=20240802T111000, start_date=20240802T121943, end_date=20240802T121944
[2024-08-02T12:19:44.458+0000] {standard_task_runner.py:110} ERROR - Failed to execute job 363 for task Carga_Dimensao_user_type (column "lead" does not exist
LINE 3:             VALUES (Lead)
                            ^
; 1835)
[2024-08-02T12:19:45.029+0000] {local_task_job_runner.py:243} INFO - Task exited with return code 1
[2024-08-02T12:19:45.250+0000] {local_task_job_runner.py:222} INFO - ::endgroup::
