[2024-08-03T17:24:43.406+0000] {local_task_job_runner.py:120} INFO - ::group::Pre task execution logs
[2024-08-03T17:24:43.857+0000] {taskinstance.py:2076} INFO - Dependencies all met for dep_context=non-requeueable deps ti=<TaskInstance: etl_dag.extract_api scheduled__2024-08-03T12:00:00+00:00 [queued]>
[2024-08-03T17:24:44.143+0000] {taskinstance.py:2076} INFO - Dependencies all met for dep_context=requeueable deps ti=<TaskInstance: etl_dag.extract_api scheduled__2024-08-03T12:00:00+00:00 [queued]>
[2024-08-03T17:24:44.164+0000] {taskinstance.py:2306} INFO - Starting attempt 6 of 6
[2024-08-03T17:24:44.890+0000] {taskinstance.py:2330} INFO - Executing <Task(SimpleHttpOperator): extract_api> on 2024-08-03 12:00:00+00:00
[2024-08-03T17:24:45.478+0000] {standard_task_runner.py:90} INFO - Running: ['***', 'tasks', 'run', 'etl_dag', 'extract_api', 'scheduled__2024-08-03T12:00:00+00:00', '--job-id', '582', '--raw', '--subdir', 'DAGS_FOLDER/etl_dag.py', '--cfg-path', '/tmp/tmpngt17cp7']
[2024-08-03T17:24:45.550+0000] {standard_task_runner.py:91} INFO - Job 582: Subtask extract_api
[2024-08-03T17:24:45.469+0000] {warnings.py:112} WARNING - /home/***/.local/lib/python3.12/site-packages/***/task/task_runner/standard_task_runner.py:62: DeprecationWarning: This process (pid=3138) is multi-threaded, use of fork() may lead to deadlocks in the child.
  pid = os.fork()

[2024-08-03T17:24:45.590+0000] {standard_task_runner.py:64} INFO - Started process 3177 to run task
[2024-08-03T17:24:46.764+0000] {task_command.py:426} INFO - Running <TaskInstance: etl_dag.extract_api scheduled__2024-08-03T12:00:00+00:00 [running]> on host 69633e19c226
[2024-08-03T17:24:48.021+0000] {taskinstance.py:2648} INFO - Exporting env vars: AIRFLOW_CTX_DAG_OWNER='Gabriel Almeida' AIRFLOW_CTX_DAG_ID='etl_dag' AIRFLOW_CTX_TASK_ID='extract_api' AIRFLOW_CTX_EXECUTION_DATE='2024-08-03T12:00:00+00:00' AIRFLOW_CTX_TRY_NUMBER='6' AIRFLOW_CTX_DAG_RUN_ID='scheduled__2024-08-03T12:00:00+00:00'
[2024-08-03T17:24:48.101+0000] {taskinstance.py:430} INFO - ::endgroup::
[2024-08-03T17:24:48.116+0000] {http.py:173} INFO - Calling HTTP method
[2024-08-03T17:24:48.359+0000] {base.py:84} INFO - Using connection ID 'api_connection' for task execution.
[2024-08-03T17:24:48.523+0000] {base.py:84} INFO - Using connection ID 'api_connection' for task execution.
[2024-08-03T17:24:48.869+0000] {http.py:243} WARNING - HTTPSConnectionPool(host='app.alunos.me', port=443): Max retries exceeded with url: /api/ahoy_viewer_ti (Caused by NameResolutionError("<urllib3.connection.HTTPSConnection object at 0xffffaf6c5430>: Failed to resolve 'app.alunos.me' ([Errno -2] Name or service not known)")) Tenacity will retry to execute the operation
[2024-08-03T17:24:48.956+0000] {taskinstance.py:441} INFO - ::group::Post task execution logs
[2024-08-03T17:24:48.992+0000] {taskinstance.py:2905} ERROR - Task failed with exception
Traceback (most recent call last):
  File "/home/airflow/.local/lib/python3.12/site-packages/urllib3/connection.py", line 203, in _new_conn
    sock = connection.create_connection(
           ^^^^^^^^^^^^^^^^^^^^^^^^^^^^^
  File "/home/airflow/.local/lib/python3.12/site-packages/urllib3/util/connection.py", line 60, in create_connection
    for res in socket.getaddrinfo(host, port, family, socket.SOCK_STREAM):
               ^^^^^^^^^^^^^^^^^^^^^^^^^^^^^^^^^^^^^^^^^^^^^^^^^^^^^^^^^^
  File "/usr/local/lib/python3.12/socket.py", line 964, in getaddrinfo
    for res in _socket.getaddrinfo(host, port, family, type, proto, flags):
               ^^^^^^^^^^^^^^^^^^^^^^^^^^^^^^^^^^^^^^^^^^^^^^^^^^^^^^^^^^^
socket.gaierror: [Errno -2] Name or service not known

The above exception was the direct cause of the following exception:

Traceback (most recent call last):
  File "/home/airflow/.local/lib/python3.12/site-packages/urllib3/connectionpool.py", line 791, in urlopen
    response = self._make_request(
               ^^^^^^^^^^^^^^^^^^^
  File "/home/airflow/.local/lib/python3.12/site-packages/urllib3/connectionpool.py", line 492, in _make_request
    raise new_e
  File "/home/airflow/.local/lib/python3.12/site-packages/urllib3/connectionpool.py", line 468, in _make_request
    self._validate_conn(conn)
  File "/home/airflow/.local/lib/python3.12/site-packages/urllib3/connectionpool.py", line 1097, in _validate_conn
    conn.connect()
  File "/home/airflow/.local/lib/python3.12/site-packages/urllib3/connection.py", line 611, in connect
    self.sock = sock = self._new_conn()
                       ^^^^^^^^^^^^^^^^
  File "/home/airflow/.local/lib/python3.12/site-packages/urllib3/connection.py", line 210, in _new_conn
    raise NameResolutionError(self.host, self, e) from e
urllib3.exceptions.NameResolutionError: <urllib3.connection.HTTPSConnection object at 0xffffaf6c5430>: Failed to resolve 'app.alunos.me' ([Errno -2] Name or service not known)

The above exception was the direct cause of the following exception:

Traceback (most recent call last):
  File "/home/airflow/.local/lib/python3.12/site-packages/requests/adapters.py", line 667, in send
    resp = conn.urlopen(
           ^^^^^^^^^^^^^
  File "/home/airflow/.local/lib/python3.12/site-packages/urllib3/connectionpool.py", line 845, in urlopen
    retries = retries.increment(
              ^^^^^^^^^^^^^^^^^^
  File "/home/airflow/.local/lib/python3.12/site-packages/urllib3/util/retry.py", line 515, in increment
    raise MaxRetryError(_pool, url, reason) from reason  # type: ignore[arg-type]
    ^^^^^^^^^^^^^^^^^^^^^^^^^^^^^^^^^^^^^^^^^^^^^^^^^^^
urllib3.exceptions.MaxRetryError: HTTPSConnectionPool(host='app.alunos.me', port=443): Max retries exceeded with url: /api/ahoy_viewer_ti (Caused by NameResolutionError("<urllib3.connection.HTTPSConnection object at 0xffffaf6c5430>: Failed to resolve 'app.alunos.me' ([Errno -2] Name or service not known)"))

During handling of the above exception, another exception occurred:

Traceback (most recent call last):
  File "/home/airflow/.local/lib/python3.12/site-packages/airflow/models/taskinstance.py", line 465, in _execute_task
    result = _execute_callable(context=context, **execute_callable_kwargs)
             ^^^^^^^^^^^^^^^^^^^^^^^^^^^^^^^^^^^^^^^^^^^^^^^^^^^^^^^^^^^^^
  File "/home/airflow/.local/lib/python3.12/site-packages/airflow/models/taskinstance.py", line 432, in _execute_callable
    return execute_callable(context=context, **execute_callable_kwargs)
           ^^^^^^^^^^^^^^^^^^^^^^^^^^^^^^^^^^^^^^^^^^^^^^^^^^^^^^^^^^^^
  File "/home/airflow/.local/lib/python3.12/site-packages/airflow/models/baseoperator.py", line 401, in wrapper
    return func(self, *args, **kwargs)
           ^^^^^^^^^^^^^^^^^^^^^^^^^^^
  File "/home/airflow/.local/lib/python3.12/site-packages/airflow/providers/http/operators/http.py", line 170, in execute
    return self.execute_sync(context=context)
           ^^^^^^^^^^^^^^^^^^^^^^^^^^^^^^^^^^
  File "/home/airflow/.local/lib/python3.12/site-packages/airflow/providers/http/operators/http.py", line 179, in execute_sync
    response = self.hook.run(self.endpoint, self.data, self.headers, self.extra_options)
               ^^^^^^^^^^^^^^^^^^^^^^^^^^^^^^^^^^^^^^^^^^^^^^^^^^^^^^^^^^^^^^^^^^^^^^^^^
  File "/home/airflow/.local/lib/python3.12/site-packages/airflow/providers/http/hooks/http.py", line 188, in run
    return self.run_and_check(session, prepped_request, extra_options)
           ^^^^^^^^^^^^^^^^^^^^^^^^^^^^^^^^^^^^^^^^^^^^^^^^^^^^^^^^^^^
  File "/home/airflow/.local/lib/python3.12/site-packages/airflow/providers/http/hooks/http.py", line 244, in run_and_check
    raise ex
  File "/home/airflow/.local/lib/python3.12/site-packages/airflow/providers/http/hooks/http.py", line 236, in run_and_check
    response = session.send(prepped_request, **send_kwargs)
               ^^^^^^^^^^^^^^^^^^^^^^^^^^^^^^^^^^^^^^^^^^^^
  File "/home/airflow/.local/lib/python3.12/site-packages/requests/sessions.py", line 703, in send
    r = adapter.send(request, **kwargs)
        ^^^^^^^^^^^^^^^^^^^^^^^^^^^^^^^
  File "/home/airflow/.local/lib/python3.12/site-packages/requests/adapters.py", line 700, in send
    raise ConnectionError(e, request=request)
requests.exceptions.ConnectionError: HTTPSConnectionPool(host='app.alunos.me', port=443): Max retries exceeded with url: /api/ahoy_viewer_ti (Caused by NameResolutionError("<urllib3.connection.HTTPSConnection object at 0xffffaf6c5430>: Failed to resolve 'app.alunos.me' ([Errno -2] Name or service not known)"))
[2024-08-03T17:24:49.737+0000] {taskinstance.py:1206} INFO - Marking task as FAILED. dag_id=etl_dag, task_id=extract_api, run_id=scheduled__2024-08-03T12:00:00+00:00, execution_date=20240803T120000, start_date=20240803T172443, end_date=20240803T172449
[2024-08-03T17:24:49.978+0000] {standard_task_runner.py:110} ERROR - Failed to execute job 582 for task extract_api (HTTPSConnectionPool(host='app.alunos.me', port=443): Max retries exceeded with url: /api/ahoy_viewer_ti (Caused by NameResolutionError("<urllib3.connection.HTTPSConnection object at 0xffffaf6c5430>: Failed to resolve 'app.alunos.me' ([Errno -2] Name or service not known)")); 3177)
[2024-08-03T17:24:50.183+0000] {local_task_job_runner.py:243} INFO - Task exited with return code 1
[2024-08-03T17:24:50.741+0000] {warnings.py:112} WARNING - /home/***/.local/lib/python3.12/site-packages/***/models/baseoperator.py:1297: AirflowProviderDeprecationWarning: Call to deprecated class PostgresOperator. (Please use `***.providers.common.sql.operators.sql.SQLExecuteQueryOperator`.Also, you can provide `hook_params={'schema': <database>}`.)
  result = cls.__new__(cls)

[2024-08-03T17:24:50.823+0000] {warnings.py:112} WARNING - /home/***/.local/lib/python3.12/site-packages/***/models/baseoperator.py:1297: AirflowProviderDeprecationWarning: Call to deprecated class SimpleHttpOperator. (Class `SimpleHttpOperator` is deprecated and will be removed in a future release. Please use `HttpOperator` instead.)
  result = cls.__new__(cls)

[2024-08-03T17:24:51.244+0000] {taskinstance.py:3503} INFO - 0 downstream tasks scheduled from follow-on schedule check
[2024-08-03T17:24:51.336+0000] {local_task_job_runner.py:222} INFO - ::endgroup::
