[2024-08-05T11:52:06.306+0000] {local_task_job_runner.py:120} INFO - ::group::Pre task execution logs
[2024-08-05T11:52:06.329+0000] {taskinstance.py:2076} INFO - Dependencies all met for dep_context=non-requeueable deps ti=<TaskInstance: dag_email_on_failure.failing_task manual__2024-08-05T11:52:05.319372+00:00 [queued]>
[2024-08-05T11:52:06.337+0000] {taskinstance.py:2076} INFO - Dependencies all met for dep_context=requeueable deps ti=<TaskInstance: dag_email_on_failure.failing_task manual__2024-08-05T11:52:05.319372+00:00 [queued]>
[2024-08-05T11:52:06.337+0000] {taskinstance.py:2306} INFO - Starting attempt 1 of 2
[2024-08-05T11:52:06.347+0000] {taskinstance.py:2330} INFO - Executing <Task(PythonOperator): failing_task> on 2024-08-05 11:52:05.319372+00:00
[2024-08-05T11:52:06.351+0000] {warnings.py:112} WARNING - /home/***/.local/lib/python3.12/site-packages/***/task/task_runner/standard_task_runner.py:62: DeprecationWarning: This process (pid=70) is multi-threaded, use of fork() may lead to deadlocks in the child.
  pid = os.fork()

[2024-08-05T11:52:06.352+0000] {standard_task_runner.py:90} INFO - Running: ['***', 'tasks', 'run', 'dag_email_on_failure', 'failing_task', 'manual__2024-08-05T11:52:05.319372+00:00', '--job-id', '1709', '--raw', '--subdir', 'DAGS_FOLDER/email.py', '--cfg-path', '/tmp/tmpaz6h3v2h']
[2024-08-05T11:52:06.354+0000] {standard_task_runner.py:64} INFO - Started process 71 to run task
[2024-08-05T11:52:06.355+0000] {standard_task_runner.py:91} INFO - Job 1709: Subtask failing_task
[2024-08-05T11:52:06.386+0000] {task_command.py:426} INFO - Running <TaskInstance: dag_email_on_failure.failing_task manual__2024-08-05T11:52:05.319372+00:00 [running]> on host c2d77eaf5a09
[2024-08-05T11:52:06.444+0000] {taskinstance.py:2648} INFO - Exporting env vars: AIRFLOW_CTX_DAG_OWNER='***' AIRFLOW_CTX_DAG_ID='dag_email_on_failure' AIRFLOW_CTX_TASK_ID='failing_task' AIRFLOW_CTX_EXECUTION_DATE='2024-08-05T11:52:05.319372+00:00' AIRFLOW_CTX_TRY_NUMBER='1' AIRFLOW_CTX_DAG_RUN_ID='manual__2024-08-05T11:52:05.319372+00:00'
[2024-08-05T11:52:06.445+0000] {taskinstance.py:430} INFO - ::endgroup::
[2024-08-05T11:52:06.461+0000] {taskinstance.py:441} INFO - ::group::Post task execution logs
[2024-08-05T11:52:06.462+0000] {taskinstance.py:2905} ERROR - Task failed with exception
Traceback (most recent call last):
  File "/home/airflow/.local/lib/python3.12/site-packages/airflow/models/taskinstance.py", line 465, in _execute_task
    result = _execute_callable(context=context, **execute_callable_kwargs)
             ^^^^^^^^^^^^^^^^^^^^^^^^^^^^^^^^^^^^^^^^^^^^^^^^^^^^^^^^^^^^^
  File "/home/airflow/.local/lib/python3.12/site-packages/airflow/models/taskinstance.py", line 432, in _execute_callable
    return execute_callable(context=context, **execute_callable_kwargs)
           ^^^^^^^^^^^^^^^^^^^^^^^^^^^^^^^^^^^^^^^^^^^^^^^^^^^^^^^^^^^^
  File "/home/airflow/.local/lib/python3.12/site-packages/airflow/models/baseoperator.py", line 401, in wrapper
    return func(self, *args, **kwargs)
           ^^^^^^^^^^^^^^^^^^^^^^^^^^^
  File "/home/airflow/.local/lib/python3.12/site-packages/airflow/operators/python.py", line 235, in execute
    return_value = self.execute_callable()
                   ^^^^^^^^^^^^^^^^^^^^^^^
  File "/home/airflow/.local/lib/python3.12/site-packages/airflow/operators/python.py", line 252, in execute_callable
    return self.python_callable(*self.op_args, **self.op_kwargs)
           ^^^^^^^^^^^^^^^^^^^^^^^^^^^^^^^^^^^^^^^^^^^^^^^^^^^^^
  File "/opt/airflow/dags/email.py", line 8, in task_that_fails
    raise ValueError("This is an intentional failure.")
ValueError: This is an intentional failure.
[2024-08-05T11:52:06.469+0000] {taskinstance.py:1206} INFO - Marking task as UP_FOR_RETRY. dag_id=dag_email_on_failure, task_id=failing_task, run_id=manual__2024-08-05T11:52:05.319372+00:00, execution_date=20240805T115205, start_date=20240805T115206, end_date=20240805T115206
[2024-08-05T11:52:06.478+0000] {standard_task_runner.py:110} ERROR - Failed to execute job 1709 for task failing_task (This is an intentional failure.; 71)
[2024-08-05T11:52:06.493+0000] {local_task_job_runner.py:243} INFO - Task exited with return code 1
[2024-08-05T11:52:06.504+0000] {taskinstance.py:3503} INFO - 0 downstream tasks scheduled from follow-on schedule check
[2024-08-05T11:52:06.506+0000] {local_task_job_runner.py:222} INFO - ::endgroup::
