[2024-08-01T01:21:22.746+0000] {local_task_job_runner.py:120} INFO - ::group::Pre task execution logs
[2024-08-01T01:21:22.760+0000] {taskinstance.py:2076} INFO - Dependencies all met for dep_context=non-requeueable deps ti=<TaskInstance: testebanco.teste manual__2024-08-01T01:21:21.473488+00:00 [queued]>
[2024-08-01T01:21:22.763+0000] {taskinstance.py:2076} INFO - Dependencies all met for dep_context=requeueable deps ti=<TaskInstance: testebanco.teste manual__2024-08-01T01:21:21.473488+00:00 [queued]>
[2024-08-01T01:21:22.763+0000] {taskinstance.py:2306} INFO - Starting attempt 1 of 1
[2024-08-01T01:21:22.769+0000] {taskinstance.py:2330} INFO - Executing <Task(PostgresOperator): teste> on 2024-08-01 01:21:21.473488+00:00
[2024-08-01T01:21:22.776+0000] {warnings.py:112} WARNING - /home/***/.local/lib/python3.12/site-packages/***/task/task_runner/standard_task_runner.py:62: DeprecationWarning: This process (pid=407) is multi-threaded, use of fork() may lead to deadlocks in the child.
  pid = os.fork()

[2024-08-01T01:21:22.777+0000] {standard_task_runner.py:64} INFO - Started process 409 to run task
[2024-08-01T01:21:22.778+0000] {standard_task_runner.py:90} INFO - Running: ['***', 'tasks', 'run', 'testebanco', 'teste', 'manual__2024-08-01T01:21:21.473488+00:00', '--job-id', '89', '--raw', '--subdir', 'DAGS_FOLDER/teste_dag.py', '--cfg-path', '/tmp/tmpey69d3qz']
[2024-08-01T01:21:22.779+0000] {standard_task_runner.py:91} INFO - Job 89: Subtask teste
[2024-08-01T01:21:22.812+0000] {task_command.py:426} INFO - Running <TaskInstance: testebanco.teste manual__2024-08-01T01:21:21.473488+00:00 [running]> on host e27a9ccca098
[2024-08-01T01:21:22.857+0000] {taskinstance.py:2648} INFO - Exporting env vars: AIRFLOW_CTX_DAG_OWNER='***' AIRFLOW_CTX_DAG_ID='testebanco' AIRFLOW_CTX_TASK_ID='teste' AIRFLOW_CTX_EXECUTION_DATE='2024-08-01T01:21:21.473488+00:00' AIRFLOW_CTX_TRY_NUMBER='1' AIRFLOW_CTX_DAG_RUN_ID='manual__2024-08-01T01:21:21.473488+00:00'
[2024-08-01T01:21:22.858+0000] {taskinstance.py:430} INFO - ::endgroup::
[2024-08-01T01:21:22.858+0000] {sql.py:282} INFO - Executing: SELECT NOW()
[2024-08-01T01:21:22.864+0000] {base.py:84} INFO - Using connection ID 'postgres_conn' for task execution.
[2024-08-01T01:21:22.873+0000] {base.py:84} INFO - Using connection ID 'postgres_conn' for task execution.
[2024-08-01T01:21:22.877+0000] {taskinstance.py:441} INFO - ::group::Post task execution logs
[2024-08-01T01:21:22.878+0000] {taskinstance.py:2905} ERROR - Task failed with exception
Traceback (most recent call last):
  File "/home/airflow/.local/lib/python3.12/site-packages/airflow/models/taskinstance.py", line 465, in _execute_task
    result = _execute_callable(context=context, **execute_callable_kwargs)
             ^^^^^^^^^^^^^^^^^^^^^^^^^^^^^^^^^^^^^^^^^^^^^^^^^^^^^^^^^^^^^
  File "/home/airflow/.local/lib/python3.12/site-packages/airflow/models/taskinstance.py", line 432, in _execute_callable
    return execute_callable(context=context, **execute_callable_kwargs)
           ^^^^^^^^^^^^^^^^^^^^^^^^^^^^^^^^^^^^^^^^^^^^^^^^^^^^^^^^^^^^
  File "/home/airflow/.local/lib/python3.12/site-packages/airflow/models/baseoperator.py", line 401, in wrapper
    return func(self, *args, **kwargs)
           ^^^^^^^^^^^^^^^^^^^^^^^^^^^
  File "/home/airflow/.local/lib/python3.12/site-packages/airflow/providers/common/sql/operators/sql.py", line 288, in execute
    output = hook.run(
             ^^^^^^^^^
  File "/home/airflow/.local/lib/python3.12/site-packages/airflow/providers/common/sql/hooks/sql.py", line 438, in run
    with self._create_autocommit_connection(autocommit) as conn:
  File "/usr/local/lib/python3.12/contextlib.py", line 137, in __enter__
    return next(self.gen)
           ^^^^^^^^^^^^^^
  File "/home/airflow/.local/lib/python3.12/site-packages/airflow/providers/common/sql/hooks/sql.py", line 560, in _create_autocommit_connection
    with closing(self.get_conn()) as conn:
                 ^^^^^^^^^^^^^^^
  File "/home/airflow/.local/lib/python3.12/site-packages/airflow/providers/postgres/hooks/postgres.py", line 175, in get_conn
    self.conn = psycopg2.connect(**conn_args)
                ^^^^^^^^^^^^^^^^^^^^^^^^^^^^^
  File "/home/airflow/.local/lib/python3.12/site-packages/psycopg2/__init__.py", line 122, in connect
    conn = _connect(dsn, connection_factory=connection_factory, **kwasync)
           ^^^^^^^^^^^^^^^^^^^^^^^^^^^^^^^^^^^^^^^^^^^^^^^^^^^^^^^^^^^^^^^
psycopg2.OperationalError: connection to server at "localhost" (::1), port 5432 failed: Connection refused
	Is the server running on that host and accepting TCP/IP connections?
connection to server at "localhost" (127.0.0.1), port 5432 failed: Connection refused
	Is the server running on that host and accepting TCP/IP connections?

[2024-08-01T01:21:22.893+0000] {taskinstance.py:1206} INFO - Marking task as FAILED. dag_id=***banco, task_id=***, run_id=manual__2024-08-01T01:21:21.473488+00:00, execution_date=20240801T012121, start_date=20240801T012122, end_date=20240801T012122
[2024-08-01T01:21:22.918+0000] {standard_task_runner.py:110} ERROR - Failed to execute job 89 for task *** (connection to server at "localhost" (::1), port 5432 failed: Connection refused
	Is the server running on that host and accepting TCP/IP connections?
connection to server at "localhost" (127.0.0.1), port 5432 failed: Connection refused
	Is the server running on that host and accepting TCP/IP connections?
; 409)
[2024-08-01T01:21:22.962+0000] {local_task_job_runner.py:243} INFO - Task exited with return code 1
[2024-08-01T01:21:23.002+0000] {taskinstance.py:3503} INFO - 0 downstream tasks scheduled from follow-on schedule check
[2024-08-01T01:21:23.007+0000] {local_task_job_runner.py:222} INFO - ::endgroup::
